{
  "artifacts": [],
  "command": "my_main",
  "experiment": {
    "base_dir": "/home/cs/Documents/maddpg/experiments",
    "dependencies": [
      "munch==2.3.2",
      "numpy==1.15.4",
      "pymongo==3.7.2",
      "PyYAML==3.13",
      "sacred==0.7.4",
      "tensorflow-gpu==1.12.0"
    ],
    "mainfile": "train.py",
    "name": "pymarl",
    "repositories": [],
    "sources": [
      [
        "train.py",
        "_sources/train_1280a324bdecb8cbdcff04c5c55c019d.py"
      ]
    ]
  },
  "fail_trace": [
    "Traceback (most recent call last):\n",
    "  File \"/home/cs/Tools/pycharm/helpers/pydev/_pydevd_bundle/pydevd_frame.py\", line 620, in trace_dispatch\n    self.do_wait_suspend(thread, frame, event, arg)\n",
    "  File \"/home/cs/Tools/pycharm/helpers/pydev/_pydevd_bundle/pydevd_frame.py\", line 125, in do_wait_suspend\n    self._args[0].do_wait_suspend(*args, **kwargs)\n",
    "  File \"/home/cs/Tools/pycharm/helpers/pydev/pydevd.py\", line 812, in do_wait_suspend\n    time.sleep(0.01)\n",
    "KeyboardInterrupt\n",
    "\nDuring handling of the above exception, another exception occurred:\n\n",
    "Traceback (most recent call last):\n",
    "  File \"/home/cs/Documents/maddpg/venv/maddpg/lib/python3.6/site-packages/sacred/config/captured_function.py\", line 46, in captured_function\n    result = wrapped(*args, **kwargs)\n",
    "  File \"/home/cs/Documents/maddpg/experiments/train.py\", line 272, in my_main\n    train(arglist, logger)\n",
    "  File \"/home/cs/Documents/maddpg/experiments/train.py\", line 177, in train\n    for agent in trainers:\n",
    "  File \"/home/cs/Documents/maddpg/experiments/train.py\", line 177, in train\n    for agent in trainers:\n",
    "  File \"/home/cs/Tools/pycharm/helpers/pydev/_pydevd_bundle/pydevd_frame.py\", line 628, in trace_dispatch\n    traceback.print_exc()\n",
    "  File \"/usr/lib/python3.6/traceback.py\", line 159, in print_exc\n    print_exception(*sys.exc_info(), limit=limit, file=file, chain=chain)\n",
    "  File \"/usr/lib/python3.6/traceback.py\", line 101, in print_exception\n    print(line, file=file, end=\"\")\n",
    "BrokenPipeError: [Errno 32] Broken pipe\n"
  ],
  "heartbeat": "2018-11-16T21:09:10.852261",
  "host": {
    "ENV": {},
    "cpu": "Intel(R) Core(TM) i7-7820HK CPU @ 2.90GHz",
    "gpus": {
      "driver_version": "390.77",
      "gpus": [
        {
          "model": "GeForce GTX 1080 with Max-Q Design",
          "persistence_mode": false,
          "total_memory": 8114
        }
      ]
    },
    "hostname": "ruby",
    "os": [
      "Linux",
      "Linux-4.15.0-39-generic-x86_64-with-Ubuntu-18.04-bionic"
    ],
    "python_version": "3.6.6"
  },
  "meta": {
    "command": "my_main",
    "options": {
      "--beat_interval": null,
      "--capture": null,
      "--comment": null,
      "--debug": false,
      "--enforce_clean": false,
      "--file_storage": null,
      "--force": false,
      "--help": false,
      "--loglevel": null,
      "--mongo_db": null,
      "--name": null,
      "--pdb": false,
      "--print_config": false,
      "--priority": null,
      "--queue": false,
      "--sql": null,
      "--tiny_db": null,
      "--unobserved": false,
      "COMMAND": null,
      "UPDATE": [],
      "help": false,
      "with": false
    }
  },
  "resources": [],
  "result": null,
  "start_time": "2018-11-16T20:47:07.266886",
  "status": "FAILED",
  "stop_time": "2018-11-16T21:09:10.863696"
}